<?xml version="1.0" encoding="utf-8"?>
<!-- This URDF was automatically created by SolidWorks to URDF Exporter! Originally created by Stephen Brawner (brawner@gmail.com) 
     Commit Version: 1.6.0-4-g7f85cfe  Build Version: 1.6.7995.38578
     For more information, please see http://wiki.ros.org/sw_urdf_exporter -->
<robot
  name="Armor_Robot">
  <link
    name="base_link">
    <inertial>
      <origin
        xyz="0 1.84212725368865E-17 0.0416161371560982"
        rpy="0 0 0" />
      <mass
        value="2.82025938303669" />
      <inertia
        ixx="0.00536061385559418"
        ixy="1.9347577475559E-19"
        ixz="1.05879118406788E-19"
        iyy="0.421962176355594"
        iyz="-8.392727982218E-20"
        izz="0.424580430670725" />
    </inertial>
    <visual>
      <origin
        xyz="0 0 0"
        rpy="0 0 0" />
      <geometry>
        <mesh
          filename="package://Armor_Robot/meshes/base_link.STL" />
      </geometry>
      <material
        name="">
        <color
          rgba="1 1 1 1" />
      </material>
    </visual>
    <collision>
      <origin
        xyz="0 0 0"
        rpy="0 0 0" />
      <geometry>
        <mesh
          filename="package://Armor_Robot/meshes/base_link.STL" />
      </geometry>
    </collision>
  </link>
  <link
    name="move_link">
    <inertial>
      <origin
        xyz="0 4.8450284582946E-19 0.035"
        rpy="0 0 0" />
      <mass
        value="0.137444678594553" />
      <inertia
        ixx="7.75989747898417E-05"
        ixy="0"
        ixz="-2.32406525320738E-37"
        iyy="7.75989747898417E-05"
        iyz="2.06367498512661E-37"
        izz="4.2951462060798E-05" />
    </inertial>
    <visual>
      <origin
        xyz="0 0 0"
        rpy="0 0 0" />
      <geometry>
        <mesh
          filename="package://Armor_Robot/meshes/move_link.STL" />
      </geometry>
      <material
        name="">
        <color
          rgba="1 1 1 1" />
      </material>
    </visual>
    <collision>
      <origin
        xyz="0 0 0"
        rpy="0 0 0" />
      <geometry>
        <mesh
          filename="package://Armor_Robot/meshes/move_link.STL" />
      </geometry>
    </collision>
  </link>
  <joint
    name="move_joint"
    type="prismatic">
    <origin
      xyz="0 0 0.05"
      rpy="0 0 0" />
    <parent
      link="base_link" />
    <child
      link="move_link" />
    <axis
      xyz="1 0 0" />
    <!-- <limit
      lower="1"
      upper="-1"
      effort="0"
      velocity="0" /> -->
  </joint>
  <link
    name="body_link">
    <inertial>
      <origin
        xyz="0.00323410697082154 -0.000824032968703474 0.0434141574886306"
        rpy="0 0 0" />
      <mass
        value="1.43184052536946" />
      <inertia
        ixx="0.0108592385234091"
        ixy="-6.5109540176561E-07"
        ixz="6.16574138294677E-06"
        iyy="0.0123197521096828"
        iyz="-5.52200427322481E-11"
        izz="0.0213749566414504" />
    </inertial>
    <visual>
      <origin
        xyz="0 0 0"
        rpy="0 0 0" />
      <geometry>
        <mesh
          filename="package://Armor_Robot/meshes/body_link.STL" />
      </geometry>
      <material
        name="">
        <color
          rgba="1 1 1 1" />
      </material>
    </visual>
    <collision>
      <origin
        xyz="0 0 0"
        rpy="0 0 0" />
      <geometry>
        <mesh
          filename="package://Armor_Robot/meshes/body_link.STL" />
      </geometry>
    </collision>
  </link>
  <joint
    name="body_joint"
    type="continuous">
    <origin
      xyz="0 0 0.07"
      rpy="0 0 0" />
    <parent
      link="move_link" />
    <child
      link="body_link" />
    <axis
      xyz="0 0 1" />
  </joint>
  <link
    name="Armor_link_1">
    <inertial>
      <origin
        xyz="0.214050358392136 1.38917947951772E-08 0.025955492616969"
        rpy="0 0 0" />
      <mass
        value="0.0509456108266251" />
      <inertia
        ixx="0.000140719394477131"
        ixy="-1.17811642299605E-10"
        ixz="1.63508587007056E-05"
        iyy="6.70385490466247E-05"
        iyz="4.59266050932402E-10"
        izz="8.30016361783188E-05" />
    </inertial>
    <visual>
      <origin
        xyz="0 0 0"
        rpy="0 0 0" />
      <geometry>
        <mesh
          filename="package://Armor_Robot/meshes/Armor_link_1.STL" />
      </geometry>
      <material
        name="">
        <color
          rgba="0.792156862745098 0.819607843137255 0.933333333333333 1" />
      </material>
    </visual>
    <collision>
      <origin
        xyz="0 0 0"
        rpy="0 0 0" />
      <geometry>
        <mesh
          filename="package://Armor_Robot/meshes/Armor_link_1.STL" />
      </geometry>
    </collision>
  </link>
  <joint
    name="Armor_joint_1"
    type="fixed">
    <origin
      xyz="0 0 0"
      rpy="0 0 0" />
    <parent
      link="body_link" />
    <child
      link="Armor_link_1" />
    <axis
      xyz="0 0 0" />
  </joint>
  <link
    name="Armor_light_link_1">
    <inertial>
      <origin
        xyz="0.221572317515096 -1.3918964559493E-11 0.0264442598982487"
        rpy="0 0 0" />
      <mass
        value="0.00710803062860533" />
      <inertia
        ixx="2.10647026235042E-06"
        ixy="1.27335675706779E-14"
        ixz="5.17464492683663E-07"
        iyy="2.24468146899285E-06"
        iyz="-4.34480155662021E-14"
        izz="3.13920665587173E-07" />
    </inertial>
    <visual>
      <origin
        xyz="0 0 0"
        rpy="0 0 0" />
      <geometry>
        <mesh
          filename="package://Armor_Robot/meshes/Armor_light_link_1.STL" />
      </geometry>
      <material
        name="red">
        <color
          rgba="1 0 0 1" />
      </material>
    </visual>
    <collision>
      <origin
        xyz="0 0 0"
        rpy="0 0 0" />
      <geometry>
        <mesh
          filename="package://Armor_Robot/meshes/Armor_light_link_1.STL" />
      </geometry>
    </collision>
  </link>
  <joint
    name="Armor_light_joint_1"
    type="fixed">
    <origin
      xyz="0 0 0"
      rpy="0 0 0" />
    <parent
      link="Armor_link_1" />
    <child
      link="Armor_light_link_1" />
    <axis
      xyz="0 0 0" />
  </joint>
  <link
    name="Armor_board_link_1">
    <inertial>
      <origin
        xyz="0.227888924688787 8.30714660844396E-10 0.0280694967851134"
        rpy="0 0 0" />
      <mass
        value="0.0479070281599563" />
      <inertia
        ixx="0.000126496786689491"
        ixy="7.12723217494788E-18"
        ixz="1.5917583738605E-05"
        iyy="6.37415098353665E-05"
        iyz="-3.05683412306875E-17"
        izz="7.13566591514974E-05" />
    </inertial>
    <visual>
      <origin
        xyz="0 0 0"
        rpy="0 0 0" />
      <geometry>
        <mesh
          filename="package://Armor_Robot/meshes/Armor_board_link_1.STL" />
      </geometry>
      <material
        name="black">
        <color
          rgba="0 0 0 1" />
      </material>
    </visual>
    <collision>
      <origin
        xyz="0 0 0"
        rpy="0 0 0" />
      <geometry>
        <mesh
          filename="package://Armor_Robot/meshes/Armor_board_link_1.STL" />
      </geometry>
    </collision>
  </link>
  <joint
    name="Armor_board_joint_1"
    type="fixed">
    <origin
      xyz="0 0 0"
      rpy="0 0 0" />
    <parent
      link="Armor_link_1" />
    <child
      link="Armor_board_link_1" />
    <axis
      xyz="0 0 0" />
  </joint>
  <link
    name="Armor_link_2">
    <inertial>
      <origin
        xyz="1.67830530456176E-08 -0.205050357307338 0.0559554955609896"
        rpy="0 0 0" />
      <mass
        value="0.0509456157055777" />
      <inertia
        ixx="6.70385544564837E-05"
        ixy="1.16186315319012E-10"
        ixz="4.54452911877279E-10"
        iyy="0.00014071940410559"
        iyz="-1.6350860341057E-05"
        izz="8.3001641456778E-05" />
    </inertial>
    <visual>
      <origin
        xyz="0 0 0"
        rpy="0 0 0" />
      <geometry>
        <mesh
          filename="package://Armor_Robot/meshes/Armor_link_2.STL" />
      </geometry>
      <material
        name="">
        <color
          rgba="0.792156862745098 0.819607843137255 0.933333333333333 1" />
      </material>
    </visual>
    <collision>
      <origin
        xyz="0 0 0"
        rpy="0 0 0" />
      <geometry>
        <mesh
          filename="package://Armor_Robot/meshes/Armor_link_2.STL" />
      </geometry>
    </collision>
  </link>
  <joint
    name="Armor_joint_2"
    type="fixed">
    <origin
      xyz="0 0 0"
      rpy="0 0 0" />
    <parent
      link="body_link" />
    <child
      link="Armor_link_2" />
    <axis
      xyz="0 0 0" />
  </joint>
  <link
    name="Armor_light_link_2">
    <inertial>
      <origin
        xyz="-1.39188996699929E-11 -0.212572317515096 0.0564442598982487"
        rpy="0 0 0" />
      <mass
        value="0.00710803062860532" />
      <inertia
        ixx="2.24468146899284E-06"
        ixy="-1.2733567640161E-14"
        ixz="-4.34480159558041E-14"
        iyy="2.10647026235042E-06"
        iyz="-5.17464492683663E-07"
        izz="3.13920665587172E-07" />
    </inertial>
    <visual>
      <origin
        xyz="0 0 0"
        rpy="0 0 0" />
      <geometry>
        <mesh
          filename="package://Armor_Robot/meshes/Armor_light_link_2.STL" />
      </geometry>
      <material
        name="red">
        <color
          rgba="1 0 0 1" />
      </material>
    </visual>
    <collision>
      <origin
        xyz="0 0 0"
        rpy="0 0 0" />
      <geometry>
        <mesh
          filename="package://Armor_Robot/meshes/Armor_light_link_2.STL" />
      </geometry>
    </collision>
  </link>
  <joint
    name="Armor_light_joint_2"
    type="fixed">
    <origin
      xyz="0 0 0"
      rpy="0 0 0" />
    <parent
      link="Armor_link_2" />
    <child
      link="Armor_light_link_2" />
    <axis
      xyz="0 0 0" />
  </joint>
  <link
    name="Armor_board_link_2">
    <inertial>
      <origin
        xyz="8.30714720536502E-10 -0.218888924688787 0.0580694967851135"
        rpy="0 0 0" />
      <mass
        value="0.0479070281599565" />
      <inertia
        ixx="6.37415098353667E-05"
        ixy="-7.16016095618749E-18"
        ixz="-3.06961148502026E-17"
        iyy="0.000126496786689491"
        iyz="-1.59175837386051E-05"
        izz="7.13566591514976E-05" />
    </inertial>
    <visual>
      <origin
        xyz="0 0 0"
        rpy="0 0 0" />
      <geometry>
        <mesh
          filename="package://Armor_Robot/meshes/Armor_board_link_2.STL" />
      </geometry>
       <material
        name="black">
        <color
          rgba="0 0 0 1" />
      </material>
    </visual>
    <collision>
      <origin
        xyz="0 0 0"
        rpy="0 0 0" />
      <geometry>
        <mesh
          filename="package://Armor_Robot/meshes/Armor_board_link_2.STL" />
      </geometry>
    </collision>
  </link>
  <joint
    name="Armor_board_joint_2"
    type="fixed">
    <origin
      xyz="0 0 0"
      rpy="0 0 0" />
    <parent
      link="Armor_link_2" />
    <child
      link="Armor_board_link_2" />
    <axis
      xyz="0 0 0" />
  </joint>
  <link
    name="Armor_link_3">
    <inertial>
      <origin
        xyz="-0.214050358392136 -1.38917946742684E-08 0.025955492616969"
        rpy="0 0 0" />
      <mass
        value="0.0509456108266248" />
      <inertia
        ixx="0.000140719394477132"
        ixy="-1.17811642699845E-10"
        ixz="-1.63508587007058E-05"
        iyy="6.7038549046626E-05"
        iyz="-4.59266053043003E-10"
        izz="8.30016361783179E-05" />
    </inertial>
    <visual>
      <origin
        xyz="0 0 0"
        rpy="0 0 0" />
      <geometry>
        <mesh
          filename="package://Armor_Robot/meshes/Armor_link_3.STL" />
      </geometry>
      <material
        name="">
        <color
          rgba="0.792156862745098 0.819607843137255 0.933333333333333 1" />
      </material>
    </visual>
    <collision>
      <origin
        xyz="0 0 0"
        rpy="0 0 0" />
      <geometry>
        <mesh
          filename="package://Armor_Robot/meshes/Armor_link_3.STL" />
      </geometry>
    </collision>
  </link>
  <joint
    name="Armor_joint_3"
    type="fixed">
    <origin
      xyz="0 0 0"
      rpy="0 0 0" />
    <parent
      link="body_link" />
    <child
      link="Armor_link_3" />
    <axis
      xyz="0 0 0" />
  </joint>
  <link
    name="Armor_light_link_3">
    <inertial>
      <origin
        xyz="-0.221572317515096 1.39189350319244E-11 0.0264442598982487"
        rpy="0 0 0" />
      <mass
        value="0.00710803062860533" />
      <inertia
        ixx="2.10647026235042E-06"
        ixy="1.27335675607517E-14"
        ixz="-5.17464492683664E-07"
        iyy="2.24468146899284E-06"
        iyz="4.34480156869704E-14"
        izz="3.13920665587173E-07" />
    </inertial>
    <visual>
      <origin
        xyz="0 0 0"
        rpy="0 0 0" />
      <geometry>
        <mesh
          filename="package://Armor_Robot/meshes/Armor_light_link_3.STL" />
      </geometry>
      <material
        name="red">
        <color
          rgba="1 0 0 1" />
      </material>
    </visual>
    <collision>
      <origin
        xyz="0 0 0"
        rpy="0 0 0" />
      <geometry>
        <mesh
          filename="package://Armor_Robot/meshes/Armor_light_link_3.STL" />
      </geometry>
    </collision>
  </link>
  <joint
    name="Armor_light_joint_3"
    type="fixed">
    <origin
      xyz="0 0 0"
      rpy="0 0 0" />
    <parent
      link="Armor_link_3" />
    <child
      link="Armor_light_link_3" />
    <axis
      xyz="0 0 0" />
  </joint>
  <link
    name="Armor_board_link_3">
    <inertial>
      <origin
        xyz="-0.227888924688787 -8.30714592387193E-10 0.0280694967851134"
        rpy="0 0 0" />
      <mass
        value="0.0479070281599564" />
      <inertia
        ixx="0.00012649678668949"
        ixy="7.17983656564921E-18"
        ixz="-1.5917583738605E-05"
        iyy="6.37415098353664E-05"
        iyz="3.0658687483313E-17"
        izz="7.13566591514974E-05" />
    </inertial>
    <visual>
      <origin
        xyz="0 0 0"
        rpy="0 0 0" />
      <geometry>
        <mesh
          filename="package://Armor_Robot/meshes/Armor_board_link_3.STL" />
      </geometry>
      <material
        name="black">
        <color
          rgba="0 0 0 1" />
      </material>
    </visual>
    <collision>
      <origin
        xyz="0 0 0"
        rpy="0 0 0" />
      <geometry>
        <mesh
          filename="package://Armor_Robot/meshes/Armor_board_link_3.STL" />
      </geometry>
    </collision>
  </link>
  <joint
    name="Armor_board_joint_3"
    type="fixed">
    <origin
      xyz="0 0 0"
      rpy="0 0 0" />
    <parent
      link="Armor_link_3" />
    <child
      link="Armor_board_link_3" />
    <axis
      xyz="0 0 0" />
  </joint>
  <link
    name="Armor_link_4">
    <inertial>
      <origin
        xyz="-1.67830711754295E-08 0.205050357307346 0.0559554955609644"
        rpy="0 0 0" />
      <mass
        value="0.0509456157056193" />
      <inertia
        ixx="6.70385544565383E-05"
        ixy="1.16186328155072E-10"
        ixz="-4.54452946991432E-10"
        iyy="0.000140719404105667"
        iyz="1.63508603410744E-05"
        izz="8.30016414568137E-05" />
    </inertial>
    <visual>
      <origin
        xyz="0 0 0"
        rpy="0 0 0" />
      <geometry>
        <mesh
          filename="package://Armor_Robot/meshes/Armor_link_4.STL" />
      </geometry>
      <material
        name="">
        <color
          rgba="0.792156862745098 0.819607843137255 0.933333333333333 1" />
      </material>
    </visual>
    <collision>
      <origin
        xyz="0 0 0"
        rpy="0 0 0" />
      <geometry>
        <mesh
          filename="package://Armor_Robot/meshes/Armor_link_4.STL" />
      </geometry>
    </collision>
  </link>
  <joint
    name="Armor_joint_4"
    type="fixed">
    <origin
      xyz="0 0 0"
      rpy="0 0 0" />
    <parent
      link="body_link" />
    <child
      link="Armor_link_4" />
    <axis
      xyz="0 0 0" />
  </joint>
  <link
    name="Armor_light_link_4">
    <inertial>
      <origin
        xyz="1.39190009344758E-11 0.212572317515096 0.0564442598982486"
        rpy="0 0 0" />
      <mass
        value="0.00710803062860533" />
      <inertia
        ixx="2.24468146899284E-06"
        ixy="-1.27335677096442E-14"
        ixz="4.34480165050521E-14"
        iyy="2.10647026235042E-06"
        iyz="5.17464492683663E-07"
        izz="3.13920665587172E-07" />
    </inertial>
    <visual>
      <origin
        xyz="0 0 0"
        rpy="0 0 0" />
      <geometry>
        <mesh
          filename="package://Armor_Robot/meshes/Armor_light_link_4.STL" />
      </geometry>
      <material
        name="red">
        <color
          rgba="1 0 0 1" />
      </material>
    </visual>
    <collision>
      <origin
        xyz="0 0 0"
        rpy="0 0 0" />
      <geometry>
        <mesh
          filename="package://Armor_Robot/meshes/Armor_light_link_4.STL" />
      </geometry>
    </collision>
  </link>
  <joint
    name="Armor_light_joint_4"
    type="fixed">
    <origin
      xyz="0 0 0"
      rpy="0 0 0" />
    <parent
      link="Armor_link_4" />
    <child
      link="Armor_light_link_4" />
    <axis
      xyz="0 0 0" />
  </joint>
  <link
    name="Armor_board_link_4">
    <inertial>
      <origin
        xyz="-8.30714627078274E-10 0.218888924688787 0.0580694967851134"
        rpy="0 0 0" />
      <mass
        value="0.0479070281599563" />
      <inertia
        ixx="6.37415098353665E-05"
        ixy="-7.13095439526534E-18"
        ixz="3.06344345266024E-17"
        iyy="0.000126496786689491"
        iyz="1.5917583738605E-05"
        izz="7.13566591514975E-05" />
    </inertial>
    <visual>
      <origin
        xyz="0 0 0"
        rpy="0 0 0" />
      <geometry>
        <mesh
          filename="package://Armor_Robot/meshes/Armor_board_link_4.STL" />
      </geometry>
      <material
        name="black">
        <color
          rgba="0 0 0 1" />
      </material>
    </visual>
    <collision>
      <origin
        xyz="0 0 0"
        rpy="0 0 0" />
      <geometry>
        <mesh
          filename="package://Armor_Robot/meshes/Armor_board_link_4.STL" />
      </geometry>
    </collision>
  </link>
  <joint
    name="Armor_board_joint_4"
    type="fixed">
    <origin
      xyz="0 0 0"
      rpy="0 0 0" />
    <parent
      link="Armor_link_4" />
    <child
      link="Armor_board_link_4" />
    <axis
      xyz="0 0 0" />
  </joint>
</robot>